2025-05-04 13:05:37,682 - engineio.server - INFO - Server initialized for threading.
2025-05-04 13:05:37,688 - database - INFO - Connecting to MongoDB at: mongodb+srv://kishore01062002:<your_new_password>@cluster0.mongodb.net/
2025-05-04 13:05:37,795 - database - ERROR - Database initialization error: The DNS query name does not exist: _mongodb._tcp.cluster0.mongodb.net.
Traceback (most recent call last):
  File "D:\medi predict\database.py", line 29, in initialize_db
    self.client = MongoClient(
                  ~~~~~~~~~~~^
        mongo_uri,
        ^^^^^^^^^^
    ...<4 lines>...
        w="majority"
        ^^^^^^^^^^^^
    )
    ^
  File "D:\medi predict\venv\Lib\site-packages\pymongo\mongo_client.py", line 771, in __init__
    res = uri_parser.parse_uri(
        entity,
    ...<6 lines>...
        srv_max_hosts=srv_max_hosts,
    )
  File "D:\medi predict\venv\Lib\site-packages\pymongo\uri_parser.py", line 558, in parse_uri
    nodes = dns_resolver.get_hosts()
  File "D:\medi predict\venv\Lib\site-packages\pymongo\srv_resolver.py", line 131, in get_hosts
    _, nodes = self._get_srv_response_and_hosts(True)
               ~~~~~~~~~~~~~~~~~~~~~~~~~~~~~~~~^^^^^^
  File "D:\medi predict\venv\Lib\site-packages\pymongo\srv_resolver.py", line 111, in _get_srv_response_and_hosts
    results = self._resolve_uri(encapsulate_errors)
  File "D:\medi predict\venv\Lib\site-packages\pymongo\srv_resolver.py", line 105, in _resolve_uri
    raise ConfigurationError(str(exc)) from None
pymongo.errors.ConfigurationError: The DNS query name does not exist: _mongodb._tcp.cluster0.mongodb.net.
2025-05-04 13:06:13,777 - engineio.server - INFO - Server initialized for threading.
2025-05-04 13:06:13,778 - database - INFO - Connecting to MongoDB at: mongodb+srv://kishore01062002:<your_new_password>@cluster0.mongodb.net/
2025-05-04 13:06:13,788 - database - ERROR - Database initialization error: The DNS query name does not exist: _mongodb._tcp.cluster0.mongodb.net.
Traceback (most recent call last):
  File "D:\medi predict\database.py", line 29, in initialize_db
    self.client = MongoClient(
                  ~~~~~~~~~~~^
        mongo_uri,
        ^^^^^^^^^^
    ...<4 lines>...
        w="majority"
        ^^^^^^^^^^^^
    )
    ^
  File "D:\medi predict\venv\Lib\site-packages\pymongo\mongo_client.py", line 771, in __init__
    res = uri_parser.parse_uri(
        entity,
    ...<6 lines>...
        srv_max_hosts=srv_max_hosts,
    )
  File "D:\medi predict\venv\Lib\site-packages\pymongo\uri_parser.py", line 558, in parse_uri
    nodes = dns_resolver.get_hosts()
  File "D:\medi predict\venv\Lib\site-packages\pymongo\srv_resolver.py", line 131, in get_hosts
    _, nodes = self._get_srv_response_and_hosts(True)
               ~~~~~~~~~~~~~~~~~~~~~~~~~~~~~~~~^^^^^^
  File "D:\medi predict\venv\Lib\site-packages\pymongo\srv_resolver.py", line 111, in _get_srv_response_and_hosts
    results = self._resolve_uri(encapsulate_errors)
  File "D:\medi predict\venv\Lib\site-packages\pymongo\srv_resolver.py", line 105, in _resolve_uri
    raise ConfigurationError(str(exc)) from None
pymongo.errors.ConfigurationError: The DNS query name does not exist: _mongodb._tcp.cluster0.mongodb.net.
2025-05-04 13:08:32,286 - engineio.server - INFO - Server initialized for threading.
2025-05-04 13:08:32,410 - database - ERROR - Database initialization error: The DNS query name does not exist: _mongodb._tcp.cluster0.mongodb.net.
2025-05-04 13:23:50,600 - engineio.server - INFO - Server initialized for threading.
2025-05-04 13:23:52,040 - werkzeug - INFO - [31m[1mWARNING: This is a development server. Do not use it in a production deployment. Use a production WSGI server instead.[0m
 * Running on all addresses (0.0.0.0)
 * Running on http://127.0.0.1:5000
 * Running on http://172.20.10.7:5000
2025-05-04 13:23:52,041 - werkzeug - INFO - [33mPress CTRL+C to quit[0m
2025-05-04 13:23:52,042 - werkzeug - INFO -  * Restarting with stat
2025-05-04 13:23:56,371 - engineio.server - INFO - Server initialized for threading.
2025-05-04 13:23:57,469 - werkzeug - WARNING -  * Debugger is active!
2025-05-04 13:23:57,481 - werkzeug - INFO -  * Debugger PIN: 118-518-064
2025-05-04 13:24:48,023 - werkzeug - INFO -  * Detected change in 'D:\\medi predict\\database.py', reloading
2025-05-04 13:24:48,897 - werkzeug - INFO -  * Restarting with stat
2025-05-04 13:24:53,547 - engineio.server - INFO - Server initialized for threading.
2025-05-04 13:24:53,650 - database - ERROR - Database initialization error: The DNS query name does not exist: _mongodb._tcp.cluster0.mongodb.net.
2025-05-04 13:25:04,012 - engineio.server - INFO - Server initialized for threading.
2025-05-04 13:25:04,025 - database - ERROR - Database initialization error: The DNS query name does not exist: _mongodb._tcp.cluster0.mongodb.net.
2025-05-04 13:26:39,013 - engineio.server - INFO - Server initialized for threading.
2025-05-04 13:26:39,015 - database - INFO - Connecting to MongoDB: mongodb+srv://kishore01062002:<your_new_password>@cluster0.mongodb.net/
2025-05-04 13:26:39,015 - database - INFO - Using database: medi_predict
2025-05-04 13:26:39,398 - database - ERROR - Database initialization error: The DNS query name does not exist: _mongodb._tcp.cluster0.mongodb.net.
2025-05-04 13:26:39,402 - database - ERROR - Full error details: Traceback (most recent call last):
  File "D:\medi predict\database.py", line 43, in initialize_db
    self.client = MongoClient(mongo_uri, serverSelectionTimeoutMS=5000)
                  ~~~~~~~~~~~^^^^^^^^^^^^^^^^^^^^^^^^^^^^^^^^^^^^^^^^^^
  File "D:\medi predict\venv\Lib\site-packages\pymongo\mongo_client.py", line 771, in __init__
    res = uri_parser.parse_uri(
        entity,
    ...<6 lines>...
        srv_max_hosts=srv_max_hosts,
    )
  File "D:\medi predict\venv\Lib\site-packages\pymongo\uri_parser.py", line 558, in parse_uri
    nodes = dns_resolver.get_hosts()
  File "D:\medi predict\venv\Lib\site-packages\pymongo\srv_resolver.py", line 131, in get_hosts
    _, nodes = self._get_srv_response_and_hosts(True)
               ~~~~~~~~~~~~~~~~~~~~~~~~~~~~~~~~^^^^^^
  File "D:\medi predict\venv\Lib\site-packages\pymongo\srv_resolver.py", line 111, in _get_srv_response_and_hosts
    results = self._resolve_uri(encapsulate_errors)
  File "D:\medi predict\venv\Lib\site-packages\pymongo\srv_resolver.py", line 105, in _resolve_uri
    raise ConfigurationError(str(exc)) from None
pymongo.errors.ConfigurationError: The DNS query name does not exist: _mongodb._tcp.cluster0.mongodb.net.

2025-05-04 13:28:19,033 - engineio.server - INFO - Server initialized for threading.
2025-05-04 13:28:19,037 - database - INFO - Connecting to MongoDB: mongodb+srv://kishore01062002:<your_new_password>@cluster0.mongodb.net/
2025-05-04 13:28:19,037 - database - INFO - Using database: medi_predict
2025-05-04 13:28:19,174 - database - ERROR - Database initialization error: The DNS query name does not exist: _mongodb._tcp.cluster0.mongodb.net.
2025-05-04 13:28:19,180 - database - ERROR - Full error details: Traceback (most recent call last):
  File "D:\medi predict\database.py", line 55, in initialize_db
    self.client = MongoClient(mongo_uri, serverSelectionTimeoutMS=5000)
                  ~~~~~~~~~~~^^^^^^^^^^^^^^^^^^^^^^^^^^^^^^^^^^^^^^^^^^
  File "D:\medi predict\venv\Lib\site-packages\pymongo\mongo_client.py", line 771, in __init__
    res = uri_parser.parse_uri(
        entity,
    ...<6 lines>...
        srv_max_hosts=srv_max_hosts,
    )
  File "D:\medi predict\venv\Lib\site-packages\pymongo\uri_parser.py", line 558, in parse_uri
    nodes = dns_resolver.get_hosts()
  File "D:\medi predict\venv\Lib\site-packages\pymongo\srv_resolver.py", line 131, in get_hosts
    _, nodes = self._get_srv_response_and_hosts(True)
               ~~~~~~~~~~~~~~~~~~~~~~~~~~~~~~~~^^^^^^
  File "D:\medi predict\venv\Lib\site-packages\pymongo\srv_resolver.py", line 111, in _get_srv_response_and_hosts
    results = self._resolve_uri(encapsulate_errors)
  File "D:\medi predict\venv\Lib\site-packages\pymongo\srv_resolver.py", line 105, in _resolve_uri
    raise ConfigurationError(str(exc)) from None
pymongo.errors.ConfigurationError: The DNS query name does not exist: _mongodb._tcp.cluster0.mongodb.net.

2025-05-04 13:29:18,511 - engineio.server - INFO - Server initialized for threading.
2025-05-04 13:29:18,513 - database - INFO - Connecting to MongoDB: mongodb+srv://kishore01062002:<your_new_password>@cluster0.bpzygxf.mongodb.net/
2025-05-04 13:29:18,514 - database - INFO - Using database: medi_predict
2025-05-04 13:29:19,594 - database - ERROR - Database initialization error: bad auth : Authentication failed., full error: {'ok': 0, 'errmsg': 'bad auth : Authentication failed.', 'code': 8000, 'codeName': 'AtlasError'}
2025-05-04 13:29:19,607 - database - ERROR - Full error details: Traceback (most recent call last):
  File "D:\medi predict\database.py", line 66, in initialize_db
    self.db.command('ping')
    ~~~~~~~~~~~~~~~^^^^^^^^
  File "D:\medi predict\venv\Lib\site-packages\pymongo\_csot.py", line 107, in csot_wrapper
    return func(self, *args, **kwargs)
  File "D:\medi predict\venv\Lib\site-packages\pymongo\database.py", line 890, in command
    with self.__client._conn_for_reads(read_preference, session) as (
         ~~~~~~~~~~~~~~~~~~~~~~~~~~~~~^^^^^^^^^^^^^^^^^^^^^^^^^^
  File "C:\Program Files\WindowsApps\PythonSoftwareFoundation.Python.3.13_3.13.1008.0_x64__qbz5n2kfra8p0\Lib\contextlib.py", line 141, in __enter__
    return next(self.gen)
  File "D:\medi predict\venv\Lib\site-packages\pymongo\mongo_client.py", line 1330, in _conn_from_server
    with self._checkout(server, session) as conn:
         ~~~~~~~~~~~~~~^^^^^^^^^^^^^^^^^
  File "C:\Program Files\WindowsApps\PythonSoftwareFoundation.Python.3.13_3.13.1008.0_x64__qbz5n2kfra8p0\Lib\contextlib.py", line 141, in __enter__
    return next(self.gen)
  File "D:\medi predict\venv\Lib\site-packages\pymongo\mongo_client.py", line 1252, in _checkout
    with server.checkout(handler=err_handler) as conn:
         ~~~~~~~~~~~~~~~^^^^^^^^^^^^^^^^^^^^^
  File "C:\Program Files\WindowsApps\PythonSoftwareFoundation.Python.3.13_3.13.1008.0_x64__qbz5n2kfra8p0\Lib\contextlib.py", line 141, in __enter__
    return next(self.gen)
  File "D:\medi predict\venv\Lib\site-packages\pymongo\pool.py", line 1637, in checkout
    conn = self._get_conn(handler=handler)
  File "D:\medi predict\venv\Lib\site-packages\pymongo\pool.py", line 1756, in _get_conn
    conn = self.connect(handler=handler)
  File "D:\medi predict\venv\Lib\site-packages\pymongo\pool.py", line 1607, in connect
    conn.authenticate()
    ~~~~~~~~~~~~~~~~~^^
  File "D:\medi predict\venv\Lib\site-packages\pymongo\pool.py", line 1078, in authenticate
    auth.authenticate(creds, self, reauthenticate=reauthenticate)
    ~~~~~~~~~~~~~~~~~^^^^^^^^^^^^^^^^^^^^^^^^^^^^^^^^^^^^^^^^^^^^
  File "D:\medi predict\venv\Lib\site-packages\pymongo\auth.py", line 625, in authenticate
    auth_func(credentials, conn)
    ~~~~~~~~~^^^^^^^^^^^^^^^^^^^
  File "D:\medi predict\venv\Lib\site-packages\pymongo\auth.py", line 530, in _authenticate_default
    return _authenticate_scram(credentials, conn, "SCRAM-SHA-1")
  File "D:\medi predict\venv\Lib\site-packages\pymongo\auth.py", line 257, in _authenticate_scram
    res = conn.command(source, cmd)
  File "D:\medi predict\venv\Lib\site-packages\pymongo\helpers.py", line 322, in inner
    return func(*args, **kwargs)
  File "D:\medi predict\venv\Lib\site-packages\pymongo\pool.py", line 968, in command
    return command(
        self,
    ...<20 lines>...
        write_concern=write_concern,
    )
  File "D:\medi predict\venv\Lib\site-packages\pymongo\network.py", line 192, in command
    helpers._check_command_response(
    ~~~~~~~~~~~~~~~~~~~~~~~~~~~~~~~^
        response_doc,
        ^^^^^^^^^^^^^
    ...<2 lines>...
        parse_write_concern_error=parse_write_concern_error,
        ^^^^^^^^^^^^^^^^^^^^^^^^^^^^^^^^^^^^^^^^^^^^^^^^^^^^
    )
    ^
  File "D:\medi predict\venv\Lib\site-packages\pymongo\helpers.py", line 230, in _check_command_response
    raise OperationFailure(errmsg, code, response, max_wire_version)
pymongo.errors.OperationFailure: bad auth : Authentication failed., full error: {'ok': 0, 'errmsg': 'bad auth : Authentication failed.', 'code': 8000, 'codeName': 'AtlasError'}

2025-05-04 13:30:18,446 - engineio.server - INFO - Server initialized for threading.
2025-05-04 13:30:18,447 - database - INFO - Connecting to MongoDB: mongodb+srv://kishore01062002:<your_new_password>@cluster0.bpzygxf.mongodb.net/
2025-05-04 13:30:18,448 - database - INFO - Using database: medi_predict
2025-05-04 13:30:19,531 - database - ERROR - Database initialization error: bad auth : Authentication failed., full error: {'ok': 0, 'errmsg': 'bad auth : Authentication failed.', 'code': 8000, 'codeName': 'AtlasError'}
2025-05-04 13:30:19,538 - database - ERROR - Full error details: Traceback (most recent call last):
  File "D:\medi predict\database.py", line 78, in initialize_db
    self.db.command('ping')
    ~~~~~~~~~~~~~~~^^^^^^^^
  File "D:\medi predict\venv\Lib\site-packages\pymongo\_csot.py", line 107, in csot_wrapper
    return func(self, *args, **kwargs)
  File "D:\medi predict\venv\Lib\site-packages\pymongo\database.py", line 890, in command
    with self.__client._conn_for_reads(read_preference, session) as (
         ~~~~~~~~~~~~~~~~~~~~~~~~~~~~~^^^^^^^^^^^^^^^^^^^^^^^^^^
  File "C:\Program Files\WindowsApps\PythonSoftwareFoundation.Python.3.13_3.13.1008.0_x64__qbz5n2kfra8p0\Lib\contextlib.py", line 141, in __enter__
    return next(self.gen)
  File "D:\medi predict\venv\Lib\site-packages\pymongo\mongo_client.py", line 1330, in _conn_from_server
    with self._checkout(server, session) as conn:
         ~~~~~~~~~~~~~~^^^^^^^^^^^^^^^^^
  File "C:\Program Files\WindowsApps\PythonSoftwareFoundation.Python.3.13_3.13.1008.0_x64__qbz5n2kfra8p0\Lib\contextlib.py", line 141, in __enter__
    return next(self.gen)
  File "D:\medi predict\venv\Lib\site-packages\pymongo\mongo_client.py", line 1252, in _checkout
    with server.checkout(handler=err_handler) as conn:
         ~~~~~~~~~~~~~~~^^^^^^^^^^^^^^^^^^^^^
  File "C:\Program Files\WindowsApps\PythonSoftwareFoundation.Python.3.13_3.13.1008.0_x64__qbz5n2kfra8p0\Lib\contextlib.py", line 141, in __enter__
    return next(self.gen)
  File "D:\medi predict\venv\Lib\site-packages\pymongo\pool.py", line 1637, in checkout
    conn = self._get_conn(handler=handler)
  File "D:\medi predict\venv\Lib\site-packages\pymongo\pool.py", line 1756, in _get_conn
    conn = self.connect(handler=handler)
  File "D:\medi predict\venv\Lib\site-packages\pymongo\pool.py", line 1607, in connect
    conn.authenticate()
    ~~~~~~~~~~~~~~~~~^^
  File "D:\medi predict\venv\Lib\site-packages\pymongo\pool.py", line 1078, in authenticate
    auth.authenticate(creds, self, reauthenticate=reauthenticate)
    ~~~~~~~~~~~~~~~~~^^^^^^^^^^^^^^^^^^^^^^^^^^^^^^^^^^^^^^^^^^^^
  File "D:\medi predict\venv\Lib\site-packages\pymongo\auth.py", line 625, in authenticate
    auth_func(credentials, conn)
    ~~~~~~~~~^^^^^^^^^^^^^^^^^^^
  File "D:\medi predict\venv\Lib\site-packages\pymongo\auth.py", line 530, in _authenticate_default
    return _authenticate_scram(credentials, conn, "SCRAM-SHA-1")
  File "D:\medi predict\venv\Lib\site-packages\pymongo\auth.py", line 257, in _authenticate_scram
    res = conn.command(source, cmd)
  File "D:\medi predict\venv\Lib\site-packages\pymongo\helpers.py", line 322, in inner
    return func(*args, **kwargs)
  File "D:\medi predict\venv\Lib\site-packages\pymongo\pool.py", line 968, in command
    return command(
        self,
    ...<20 lines>...
        write_concern=write_concern,
    )
  File "D:\medi predict\venv\Lib\site-packages\pymongo\network.py", line 192, in command
    helpers._check_command_response(
    ~~~~~~~~~~~~~~~~~~~~~~~~~~~~~~~^
        response_doc,
        ^^^^^^^^^^^^^
    ...<2 lines>...
        parse_write_concern_error=parse_write_concern_error,
        ^^^^^^^^^^^^^^^^^^^^^^^^^^^^^^^^^^^^^^^^^^^^^^^^^^^^
    )
    ^
  File "D:\medi predict\venv\Lib\site-packages\pymongo\helpers.py", line 230, in _check_command_response
    raise OperationFailure(errmsg, code, response, max_wire_version)
pymongo.errors.OperationFailure: bad auth : Authentication failed., full error: {'ok': 0, 'errmsg': 'bad auth : Authentication failed.', 'code': 8000, 'codeName': 'AtlasError'}

2025-05-04 13:31:10,552 - engineio.server - INFO - Server initialized for threading.
2025-05-04 13:31:12,072 - werkzeug - INFO - [31m[1mWARNING: This is a development server. Do not use it in a production deployment. Use a production WSGI server instead.[0m
 * Running on all addresses (0.0.0.0)
 * Running on http://127.0.0.1:5000
 * Running on http://172.20.10.7:5000
2025-05-04 13:31:12,072 - werkzeug - INFO - [33mPress CTRL+C to quit[0m
2025-05-04 13:31:12,073 - werkzeug - INFO -  * Restarting with stat
2025-05-04 13:31:15,541 - engineio.server - INFO - Server initialized for threading.
2025-05-04 13:31:17,474 - werkzeug - WARNING -  * Debugger is active!
2025-05-04 13:31:17,483 - werkzeug - INFO -  * Debugger PIN: 118-518-064
2025-05-04 13:32:03,318 - werkzeug - INFO -  * Detected change in 'D:\\medi predict\\app.py', reloading
2025-05-04 13:32:04,347 - werkzeug - INFO -  * Restarting with stat
2025-05-04 13:32:10,189 - engineio.server - INFO - Server initialized for threading.
2025-05-04 13:32:12,158 - werkzeug - WARNING -  * Debugger is active!
2025-05-04 13:32:12,163 - werkzeug - INFO -  * Debugger PIN: 118-518-064
2025-05-04 13:33:24,405 - werkzeug - INFO -  * Detected change in 'D:\\medi predict\\chat.py', reloading
2025-05-04 13:33:25,310 - werkzeug - INFO -  * Restarting with stat
2025-05-04 13:33:29,301 - engineio.server - INFO - Server initialized for threading.
2025-05-04 13:33:30,785 - werkzeug - WARNING -  * Debugger is active!
2025-05-04 13:33:30,792 - werkzeug - INFO -  * Debugger PIN: 118-518-064
2025-05-04 13:33:38,414 - engineio.server - INFO - Server initialized for threading.
2025-05-04 13:33:39,589 - werkzeug - INFO - [31m[1mWARNING: This is a development server. Do not use it in a production deployment. Use a production WSGI server instead.[0m
 * Running on all addresses (0.0.0.0)
 * Running on http://127.0.0.1:5000
 * Running on http://172.20.10.7:5000
2025-05-04 13:33:39,590 - werkzeug - INFO - [33mPress CTRL+C to quit[0m
2025-05-04 13:33:39,590 - werkzeug - INFO -  * Restarting with stat
2025-05-04 13:33:42,948 - engineio.server - INFO - Server initialized for threading.
2025-05-04 13:33:44,147 - werkzeug - WARNING -  * Debugger is active!
2025-05-04 13:33:44,151 - werkzeug - INFO -  * Debugger PIN: 118-518-064
